Workbook

Sheet README
B1: AI DELIVERY DATA CAPTURE — PER-UNIT EVIDENCE SPINE
B2: Purpose: turn AI-delivery assumptions (c, e, q, tokens, rework, warranty) into measured, auditable actuals per unit of work,
B3: complexity class and toolchain configuration. These values feed the pricing calculator and are the evidence base for published tier prices.
B5: SHEET DIRECTORY
B6: Object_Log — one row per unit of delivery work (the core log). Grey SAMPLE-* rows are demo data: delete before live use.
B7: Dashboard — measured c/e/q/rework/warranty/tokens per class, partner-stack vs vanilla-control uplift, and the evidence-gated calculator transfer block.
B8: Customer_Extract — the per-engagement closeout extract delivered to the customer (no tokens, models, costs or margins).
B9: Deal_Log — quotes, competitor prices and win/loss outcomes, so the value anchor recalibrates from market observations.
B10: Service_Log / Contract_Log — recurring-service delivery and contract outcomes: the measured cost-to-serve evidence required before quoting subscriptions.
B12: HOW TO USE
B13: 1. During delivery, log one row per unit of work on Object_Log. Use the dropdowns — free text breaks the Dashboard formulas.
B14: 2. Toolchain column: log normal delivery as 'Partner stack'. During Wave 1, also deliver a matched control sample (~30–50 units mirroring the class mix)
... B52: rework/warranty rows → the quality & warranty reserve inputs · per-class columns → the complexity-tier table.

Sheet Object_Log
A1: Unit ID | B1: Quote ID | C1: Engagement ID | D1: Customer ID | E1: Date Completed | F1: Unit Type | G1: Initial Complexity | H1: Final Complexity | I1: Classification Rationale | J1: Reclassified By | K1: ATC Check ID | L1: Usage Status | M1: Disposition | N1: Toolchain | O1: AI Attempted (Y/N) | P1: AI Handled (Y/N) | Q1: AI Minutes | R1: Human Minutes | S1: Review Minutes | T1: First-Pass Accept (Y/N) | U1: Rework (Y/N) | V1: Rework Minutes | W1: Rework Cycles | X1: Root Cause | Y1: Warranty Incident (Y/N) | Z1: Warranty Minutes | AA1: Regression Result | AB1: Customer Sign-off Date | AC1: Provider | AD1: Model + Version | AE1: Model Tier | AF1: Config Version | AG1: Agent Version | AH1: Retry Count | AI1: Tokens In (K) | AJ1: Tokens Out (K) | AK1: Token Source | AL1: Logged By | AM1: Countersigned By | AN1: Notes
A2: SAMPLE-001 | B2: SAMPLE-Q1 | C2: SAMPLE-ENG1 | D2: SAMPLE-CUST1 | E2: 2026-06-15 | F2: Report | G2: Simple | H2: Simple | I2: ATC severity | K2: ATC-0451 | L2: Active | M2: Remediate | N2: Partner stack | O2: Y | P2: Y | Q2: 5 | R2: 15 | S2: 8 | T2: Y | U2: N | Y2: N | AA2: Pass | AB2: 2026-06-20 | AC2: Anthropic | AD2: Sonnet 4.6 (2026-05) | AE2: Workhorse | AF2: v1.3 | AG2: v0.9 | AH2: 1 | AI2: 180 | AJ2: 25 | AK2: API export | AL2: SAMPLE-DEV1 | AM2: SAMPLE-QA1 | AN2: obsolete WRITE stmts
A3: SAMPLE-002 | B3: SAMPLE-Q1 | C3: SAMPLE-ENG1 | D3: SAMPLE-CUST1 | E3: 2026-06-15 | F3: Report | G3: Simple | H3: Simple | I3: ATC severity | K3: ATC-0452 | L3: Dormant | M3: Remediate | N3: Partner stack | O3: Y | P3: Y | Q3: 4 | R3: 12 | S3: 6 | T3: Y | U3: N | Y3: N | AA3: Pass | AB3: 2026-06-20 | AC3: Anthropic | AD3: Sonnet 4.6 (2026-05) | AE3: Workhorse | AF3: v1.3 | AG3: v0.9 | AH3: 1 | AI3: 160 | AJ3: 22 | AK3: API export | AL3: SAMPLE-DEV1 | AM3: SAMPLE-QA1
A4: SAMPLE-003 | B4: SAMPLE-Q1 | C4: SAMPLE-ENG1 | D4: SAMPLE-CUST1 | E4: 2026-06-16 | F4: Include | G4: Simple | H4: Simple | I4: Code volume | K4: ATC-0460 | L4: Active | M4: Remediate | N4: Partner stack | O4: Y | P4: Y | Q4: 6 | R4: 22 | S4: 9 | T4: Y | U4: N | Y4: N | AA4: Pass | AB4: 2026-06-22 | AC4: Anthropic | AD4: Sonnet 4.6 (2026-05) | AE4: Workhorse | AF4: v1.3 | AG4: v0.9 | AH4: 1 | AI4: 210 | AJ4: 30 | AK4: API export | AL4: SAMPLE-DEV1 | AM4: SAMPLE-QA1
A5: SAMPLE-004 | B5: SAMPLE-Q1 | C5: SAMPLE-ENG1 | D5: SAMPLE-CUST1 | E5: 2026-06-17 | F5: Function | G5: Simple | H5: Simple | I5: ATC severity | K5: ATC-0465 | L5: Active | M5: Remediate | N5: Partner stack | O5: Y | P5: Y | Q5: 5 | R5: 18 | S5: 7 | T5: N | U5: Y | V5: 35 | W5: 1 | X5: AI error | Y5: N | AA5: Fail | AB5: 2026-06-25 | AC5: Anthropic | AD5: Sonnet 4.6 (2026-05) | AE5: Workhorse | AF5: v1.3 | AG5: v0.9 | AH5: 1 | AI5: 190 | AJ5: 28 | AK5: API export | AL5: SAMPLE-DEV1 | AM5: SAMPLE-QA1 | AN5: regression fail, fixed
A6: SAMPLE-005 | B6: SAMPLE-Q1 | C6: SAMPLE-ENG1 | D6: SAMPLE-CUST1 | E6: 2026-06-18 | F6: Report | G6: Medium | H6: Medium | I6: Dependency count | K6: ATC-0470 | L6: Active | M6: Remediate | N6: Partner stack | O6: Y | P6: Y | Q6: 10 | R6: 55 | S6: 18 | T6: Y | U6: N | Y6: Y | Z6: 40 | AA6: Pass | AB6: 2026-06-26 | AC6: Anthropic | AD6: Sonnet 4.6 (2026-05) | AE6: Workhorse | AF6: v1.3 | AG6: v0.9 | AH6: 1 | AI6: 240 | AJ6: 35 | AK6: API export | AL6: SAMPLE-DEV1 | AM6: SAMPLE-QA1 | AN6: SELECT * rework; warranty fix post-acceptance
A7: SAMPLE-006 | B7: SAMPLE-Q1 | C7: SAMPLE-ENG1 | D7: SAMPLE-CUST1 | E7: 2026-06-19 | F7: Class | G7: Medium | H7: Medium | I7: Dependency count | K7: ATC-0472 | L7: Active | M7: Remediate | N7: Partner stack | O7: Y | P7: Y | Q7: 12 | R7: 60 | S7: 20 | T7: Y | U7: N | Y7: N | AA7: Pass | AB7: 2026-06-27 | AC7: Anthropic | AD7: Sonnet 4.6 (2026-05) | AE7: Workhorse | AF7: v1.3 | AG7: v0.9 | AH7: 1 | AI7: 260 | AJ7: 38 | AK7: API export | AL7: SAMPLE-DEV1 | AM7: SAMPLE-QA1
A8: SAMPLE-007 | B8: SAMPLE-Q1 | C8: SAMPLE-ENG1 | D8: SAMPLE-CUST1 | E8: 2026-06-19 | F8: Function | G8: Medium | H8: Medium | I8: ATC severity | K8: ATC-0475 | L8: Active | M8: Remediate | N8: Partner stack | O8: Y | P8: Y | Q8: 9 | R8: 50 | S8: 16 | T8: Y | U8: N | Y8: N | AA8: Pass | AB8: 2026-06-27 | AC8: Anthropic | AD8: Sonnet 4.6 (2026-05) | AE8: Workhorse | AF8: v1.3 | AG8: v0.9 | AH8: 1 | AI8: 230 | AJ8: 32 | AK8: API export | AL8: SAMPLE-DEV1 | AM8: SAMPLE-QA1
A9: SAMPLE-008 | B9: SAMPLE-Q1 | C9: SAMPLE-ENG1 | D9: SAMPLE-CUST1 | E9: 2026-06-20 | F9: Class | G9: Medium | H9: Medium | I9: Dependency count | K9: ATC-0480 | L9: Active | M9: Remediate | N9: Partner stack | O9: Y | P9: Y | Q9: 11 | R9: 68 | S9: 22 | T9: N | U9: Y | V9: 60 | W9: 2 | X9: Integration | Y9: N | AA9: Fail | AB9: 2026-06-30 | AC9: Anthropic | AD9: Opus 4.8 (2026-06) | AE9: Frontier | AF9: v1.3 | AG9: v0.9 | AH9: 2 | AI9: 280 | AJ9: 40 | AK9: API export | AL9: SAMPLE-DEV1 | AM9: SAMPLE-QA1 | AN9: complex joins
A10: SAMPLE-009 | B10: SAMPLE-Q1 | C10: SAMPLE-ENG1 | D10: SAMPLE-CUST1 | E10: 2026-06-22 | F10: Enhancement | G10: Medium | H10: Complex | I10: Dependency count | J10: Joint review | K10: ATC-0483 | L10: Active | M10: Remediate | N10: Partner stack | O10: Y | P10: Y | Q10: 25 | R10: 140 | S10: 45 | T10: Y | U10: N | Y10: N | AA10: Pass | AB10: 2026-07-02 | AC10: Anthropic | AD10: Opus 4.8 (2026-06) | AE10: Frontier | AF10: v1.3 | AG10: v0.9 | AH10: 2 | AI10: 520 | AJ10: 80 | AK10: API export | AL10: SAMPLE-DEV1 | AM10: SAMPLE-QA1 | AN10: reclassified up at joint review
A11: SAMPLE-010 | B11: SAMPLE-Q1 | C11: SAMPLE-ENG1 | D11: SAMPLE-CUST1 | E11: 2026-06-23 | F11: Enhancement | G11: Complex | H11: Complex | I11: Manual judgment | K11: ATC-0485 | L11: Active | M11: Remediate | N11: Partner stack | O11: N | P11: N | Q11: 0 | R11: 410 | S11: 0 | T11: Y | U11: N | Y11: N | AA11: Pass | AB11: 2026-07-03 | AF11: v1.3 | AG11: v0.9 | AI11: 0 | AJ11: 0 | AL11: SAMPLE-DEV1 | AM11: SAMPLE-QA1 | AN11: manual — user exit logic
A12: SAMPLE-011 | B12: SAMPLE-Q1 | C12: SAMPLE-ENG1 | D12: SAMPLE-CUST1 | E12: 2026-06-24 | F12: Interface | G12: Complex | H12: Complex | I12: Manual judgment | K12: ATC-0488 | L12: Active | M12: Rewrite | N12: Partner stack | O12: Y | P12: N | Q12: 0 | R12: 440 | S12: 0 | T12: Y | U12: N | Y12: N | AA12: Pass | AB12: 2026-07-05 | AC12: Anthropic | AD12: Sonnet 4.6 (2026-05) | AE12: Workhorse | AF12: v1.3 | AG12: v0.9 | AH12: 2 | AI12: 120 | AJ12: 10 | AK12: API export | AL12: SAMPLE-DEV1 | AM12: SAMPLE-QA1 | AN12: AI attempt abandoned — redesign
A13: SAMPLE-012 | B13: SAMPLE-Q1 | C13: SAMPLE-ENG1 | D13: SAMPLE-CUST1 | E13: 2026-06-25 | F13: Class | G13: Complex | H13: Complex | I13: Dependency count | K13: ATC-0490 | L13: Active | M13: Remediate | N13: Partner stack | O13: Y | P13: Y | Q13: 30 | R13: 160 | S13: 50 | T13: Y | U13: N | Y13: N | AA13: Pass | AB13: 2026-07-06 | AC13: Anthropic | AD13: Opus 4.8 (2026-06) | AE13: Frontier | AF13: v1.3 | AG13: v0.9 | AH13: 2 | AI13: 560 | AJ13: 85 | AK13: API export | AL13: SAMPLE-DEV1 | AM13: SAMPLE-QA1
A14: SAMPLE-013 | B14: SAMPLE-Q1 | C14: SAMPLE-ENG1 | D14: SAMPLE-CUST1 | E14: 2026-06-26 | F14: Report | G14: Simple | H14: Simple | I14: ATC severity | K14: ATC-0493 | L14: Dead | M14: Decommission | N14: Partner stack | O14: N | P14: N | Q14: 0 | R14: 20 | S14: 0 | T14: Y | U14: N | Y14: N | AA14: N/A | AB14: 2026-07-06 | AI14: 0 | AJ14: 0 | AL14: SAMPLE-DEV1 | AM14: SAMPLE-QA1 | AN14: no usage in 18 months — deleted, not remediated
A15: SAMPLE-C01 | B15: SAMPLE-Q1 | C15: SAMPLE-ENG1 | D15: SAMPLE-CUST1 | E15: 2026-06-28 | F15: Report | G15: Simple | H15: Simple | I15: ATC severity | K15: ATC-0495 | L15: Active | M15: Remediate | N15: Vanilla control | O15: Y | P15: Y | Q15: 9 | R15: 28 | S15: 14 | T15: Y | U15: N | Y15: N | AA15: Pass | AB15: 2026-07-08 | AC15: Anthropic | AD15: Sonnet 4.6 (2026-05) | AE15: Workhorse | AF15: generic-v1 | AG15: n/a | AH15: 2 | AI15: 260 | AJ15: 38 | AK15: API export | AL15: SAMPLE-DEV1 | AM15: SAMPLE-QA1 | AN15: control: generic prompts, no accelerators
A16: SAMPLE-C02 | B16: SAMPLE-Q1 | C16: SAMPLE-ENG1 | D16: SAMPLE-CUST1 | E16: 2026-06-29 | F16: Class | G16: Medium | H16: Medium | I16: Dependency count | K16: ATC-0497 | L16: Active | M16: Remediate | N16: Vanilla control | O16: Y | P16: Y | Q16: 16 | R16: 95 | S16: 30 | T16: N | U16: Y | V16: 45 | W16: 1 | X16: AI error | Y16: N | AA16: Fail | AB16: 2026-07-09 | AC16: Anthropic | AD16: Sonnet 4.6 (2026-05) | AE16: Workhorse | AF16: generic-v1 | AG16: n/a | AH16: 3 | AI16: 300 | AJ16: 45 | AK16: API export | AL16: SAMPLE-DEV1 | AM16: SAMPLE-QA1 | AN16: control sample
A17: SAMPLE-C03 | B17: SAMPLE-Q1 | C17: SAMPLE-ENG1 | D17: SAMPLE-CUST1 | E17: 2026-06-30 | F17: Enhancement | G17: Complex | H17: Complex | I17: Manual judgment | K17: ATC-0499 | L17: Active | M17: Remediate | N17: Vanilla control | O17: Y | P17: Y | Q17: 45 | R17: 230 | S17: 70 | T17: Y | U17: N | Y17: N | AA17: Pass | AB17: 2026-07-10 | AC17: Anthropic | AD17: Opus 4.8 (2026-06) | AE17: Frontier | AF17: generic-v1 | AG17: n/a | AH17: 3 | AI17: 700 | AJ17: 110 | AK17: API export | AL17: SAMPLE-DEV1 | AM17: SAMPLE-QA1 | AN17: control sample

Sheet Dashboard
A1: AI DELIVERY DASHBOARD — MEASURED c, e, q, REWORK, WARRANTY, UPLIFT
A2: All figures compute live from Object_Log. Black cells are formulas — do not edit. Decommissioned units are excluded from coverage metrics.
A4: POLICY INPUTS — edit the yellow cells
A5: Baseline min: Simple | B5: 90 | C5: Medium | D5: 210 | E5: Complex | F5: 420
A6: Source: case-example standards (blended 3.5 hrs/object). Replace with your own pre-AI effort norms.
A7: Current config version | B7: v1.3 | C7: Min units/class (pricing) | D7: 150 | E7: Rework target (blended) | F7: 0.02
A9: PANEL A — PARTNER STACK · ALL CONFIG VERSIONS (per complexity class)
A10: Class | B10: Units | C10: AI-handled | D10: c — coverage | E10: Avg AI+human min | F10: e — effort reduction | G10: Avg review min | H10: q — QA add-back | I10: Rework rate | J10: Avg rework min | K10: Warranty claim rate | L10: Tokens in K/unit | M10: Tokens out K/unit
A11: Simple | B11: =COUNTIFS(Object_Log!$N$2:$N$2000,"Partner stack",Object_Log!$M$2:$M$2000,"<>Decommission",Object_Log!$H$2:$H$2000,"Simple") -> 4 | C11: =COUNTIFS(Object_Log!$N$2:$N$2000,"Partner stack",Object_Log!$M$2:$M$2000,"<>Decommission",Object_Log!$H$2:$H$2000,"Simple",Object_Log!$P$2:$P$2000,"Y") -> 4 | D11: =IFERROR(C11/B11,0) -> 1 | E11: =IFERROR(AVERAGEIFS(Object_Log!$Q$2:$Q$2000,Object_Log!$N$2:$N$2000,"Partner stack",Object_Log!$M$2:$M$2000,"<>Decommission",Object_Log!$H$2:$H$2000,"Simple",Object_Log!$P$2:$P$2000,"Y")+AVERAGEIFS(Object_Log!$R$2:$R$2000,Object_Log!$N$2:$N$2000,"Partner stack",Object_Log!$M$2:$M$2000,"<>Decommission",Object_Log!$H$2:$H$2000,"Simple",Object_Log!$P$2:$P$2000,"Y"),0) -> 21.75 | F11: =IFERROR(1-E11/$B$5,0) -> 0.75833333 | G11: =IFERROR(AVERAGEIFS(Object_Log!$S$2:$S$2000,Object_Log!$N$2:$N$2000,"Partner stack",Object_Log!$M$2:$M$2000,"<>Decommission",Object_Log!$H$2:$H$2000,"Simple",Object_Log!$P$2:$P$2000,"Y"),0) -> 7.5 | H11: =IFERROR(G11/($B$5-E11),0) -> 0.10989011 | I11: =IFERROR(COUNTIFS(Object_Log!$N$2:$N$2000,"Partner stack",Object_Log!$M$2:$M$2000,"<>Decommission",Object_Log!$H$2:$H$2000,"Simple",Object_Log!$P$2:$P$2000,"Y",Object_Log!$U$2:$U$2000,"Y")/C11,0) -> 0.25 | J11: =IFERROR(AVERAGEIFS(Object_Log!$V$2:$V$2000,Object_Log!$N$2:$N$2000,"Partner stack",Object_Log!$M$2:$M$2000,"<>Decommission",Object_Log!$H$2:$H$2000,"Simple",Object_Log!$P$2:$P$2000,"Y",Object_Log!$U$2:$U$2000,"Y"),0) -> 35 | K11: =IFERROR(COUNTIFS(Object_Log!$N$2:$N$2000,"Partner stack",Object_Log!$M$2:$M$2000,"<>Decommission",Object_Log!$H$2:$H$2000,"Simple",Object_Log!$P$2:$P$2000,"Y",Object_Log!$Y$2:$Y$2000,"Y")/C11,0) -> 0 | L11: =IFERROR(AVERAGEIFS(Object_Log!$AI$2:$AI$2000,Object_Log!$N$2:$N$2000,"Partner stack",Object_Log!$M$2:$M$2000,"<>Decommission",Object_Log!$H$2:$H$2000,"Simple",Object_Log!$P$2:$P$2000,"Y"),0) -> 185 | M11: =IFERROR(AVERAGEIFS(Object_Log!$AJ$2:$AJ$2000,Object_Log!$N$2:$N$2000,"Partner stack",Object_Log!$M$2:$M$2000,"<>Decommission",Object_Log!$H$2:$H$2000,"Simple",Object_Log!$P$2:$P$2000,"Y"),0) -> 26.25
A12: Medium | B12: =COUNTIFS(Object_Log!$N$2:$N$2000,"Partner stack",Object_Log!$M$2:$M$2000,"<>Decommission",Object_Log!$H$2:$H$2000,"Medium") -> 4 | C12: =COUNTIFS(Object_Log!$N$2:$N$2000,"Partner stack",Object_Log!$M$2:$M$2000,"<>Decommission",Object_Log!$H$2:$H$2000,"Medium",Object_Log!$P$2:$P$2000,"Y") -> 4 | D12: =IFERROR(C12/B12,0) -> 1 | E12: =IFERROR(AVERAGEIFS(Object_Log!$Q$2:$Q$2000,Object_Log!$N$2:$N$2000,"Partner stack",Object_Log!$M$2:$M$2000,"<>Decommission",Object_Log!$H$2:$H$2000,"Medium",Object_Log!$P$2:$P$2000,"Y")+AVERAGEIFS(Object_Log!$R$2:$R$2000,Object_Log!$N$2:$N$2000,"Partner stack",Object_Log!$M$2:$M$2000,"<>Decommission",Object_Log!$H$2:$H$2000,"Medium",Object_Log!$P$2:$P$2000,"Y"),0) -> 68.75 | F12: =IFERROR(1-E12/$D$5,0) -> 0.67261905 | G12: =IFERROR(AVERAGEIFS(Object_Log!$S$2:$S$2000,Object_Log!$N$2:$N$2000,"Partner stack",Object_Log!$M$2:$M$2000,"<>Decommission",Object_Log!$H$2:$H$2000,"Medium",Object_Log!$P$2:$P$2000,"Y"),0) -> 19 | H12: =IFERROR(G12/($D$5-E12),0) -> 0.13451327 | I12: =IFERROR(COUNTIFS(Object_Log!$N$2:$N$2000,"Partner stack",Object_Log!$M$2:$M$2000,"<>Decommission",Object_Log!$H$2:$H$2000,"Medium",Object_Log!$P$2:$P$2000,"Y",Object_Log!$U$2:$U$2000,"Y")/C12,0) -> 0.25 | J12: =IFERROR(AVERAGEIFS(Object_Log!$V$2:$V$2000,Object_Log!$N$2:$N$2000,"Partner stack",Object_Log!$M$2:$M$2000,"<>Decommission",Object_Log!$H$2:$H$2000,"Medium",Object_Log!$P$2:$P$2000,"Y",Object_Log!$U$2:$U$2000,"Y"),0) -> 60 | K12: =IFERROR(COUNTIFS(Object_Log!$N$2:$N$2000,"Partner stack",Object_Log!$M$2:$M$2000,"<>Decommission",Object_Log!$H$2:$H$2000,"Medium",Object_Log!$P$2:$P$2000,"Y",Object_Log!$Y$2:$Y$2000,"Y")/C12,0) -> 0.25 | L12: =IFERROR(AVERAGEIFS(Object_Log!$AI$2:$AI$2000,Object_Log!$N$2:$N$2000,"Partner stack",Object_Log!$M$2:$M$2000,"<>Decommission",Object_Log!$H$2:$H$2000,"Medium",Object_Log!$P$2:$P$2000,"Y"),0) -> 252.5 | M12: =IFERROR(AVERAGEIFS(Object_Log!$AJ$2:$AJ$2000,Object_Log!$N$2:$N$2000,"Partner stack",Object_Log!$M$2:$M$2000,"<>Decommission",Object_Log!$H$2:$H$2000,"Medium",Object_Log!$P$2:$P$2000,"Y"),0) -> 36.25
A13: Complex | B13: =COUNTIFS(Object_Log!$N$2:$N$2000,"Partner stack",Object_Log!$M$2:$M$2000,"<>Decommission",Object_Log!$H$2:$H$2000,"Complex") -> 4 | C13: =COUNTIFS(Object_Log!$N$2:$N$2000,"Partner stack",Object_Log!$M$2:$M$2000,"<>Decommission",Object_Log!$H$2:$H$2000,"Complex",Object_Log!$P$2:$P$2000,"Y") -> 2 | D13: =IFERROR(C13/B13,0) -> 0.5 | E13: =IFERROR(AVERAGEIFS(Object_Log!$Q$2:$Q$2000,Object_Log!$N$2:$N$2000,"Partner stack",Object_Log!$M$2:$M$2000,"<>Decommission",Object_Log!$H$2:$H$2000,"Complex",Object_Log!$P$2:$P$2000,"Y")+AVERAGEIFS(Object_Log!$R$2:$R$2000,Object_Log!$N$2:$N$2000,"Partner stack",Object_Log!$M$2:$M$2000,"<>Decommission",Object_Log!$H$2:$H$2000,"Complex",Object_Log!$P$2:$P$2000,"Y"),0) -> 177.5 | F13: =IFERROR(1-E13/$F$5,0) -> 0.57738095 | G13: =IFERROR(AVERAGEIFS(Object_Log!$S$2:$S$2000,Object_Log!$N$2:$N$2000,"Partner stack",Object_Log!$M$2:$M$2000,"<>Decommission",Object_Log!$H$2:$H$2000,"Complex",Object_Log!$P$2:$P$2000,"Y"),0) -> 47.5 | H13: =IFERROR(G13/($F$5-E13),0) -> 0.19587629 | I13: =IFERROR(COUNTIFS(Object_Log!$N$2:$N$2000,"Partner stack",Object_Log!$M$2:$M$2000,"<>Decommission",Object_Log!$H$2:$H$2000,"Complex",Object_Log!$P$2:$P$2000,"Y",Object_Log!$U$2:$U$2000,"Y")/C13,0) -> 0 | J13: =IFERROR(AVERAGEIFS(Object_Log!$V$2:$V$2000,Object_Log!$N$2:$N$2000,"Partner stack",Object_Log!$M$2:$M$2000,"<>Decommission",Object_Log!$H$2:$H$2000,"Complex",Object_Log!$P$2:$P$2000,"Y",Object_Log!$U$2:$U$2000,"Y"),0) -> 0 | K13: =IFERROR(COUNTIFS(Object_Log!$N$2:$N$2000,"Partner stack",Object_Log!$M$2:$M$2000,"<>Decommission",Object_Log!$H$2:$H$2000,"Complex",Object_Log!$P$2:$P$2000,"Y",Object_Log!$Y$2:$Y$2000,"Y")/C13,0) -> 0 | L13: =IFERROR(AVERAGEIFS(Object_Log!$AI$2:$AI$2000,Object_Log!$N$2:$N$2000,"Partner stack",Object_Log!$M$2:$M$2000,"<>Decommission",Object_Log!$H$2:$H$2000,"Complex",Object_Log!$P$2:$P$2000,"Y"),0) -> 540 | M13: =IFERROR(AVERAGEIFS(Object_Log!$AJ$2:$AJ$2000,Object_Log!$N$2:$N$2000,"Partner stack",Object_Log!$M$2:$M$2000,"<>Decommission",Object_Log!$H$2:$H$2000,"Complex",Object_Log!$P$2:$P$2000,"Y"),0) -> 82.5
A14: ALL UNITS (minute-weighted) | B14: =SUM(B11:B13) -> 12 | C14: =SUM(C11:C13) -> 10 | D14: =IFERROR(C14/B14,0) -> 0.83333333 | E14: =IFERROR((C11*E11+C12*E12+C13*E13)/C14,0) -> 71.7 | F14: =IFERROR(1-(C11*E11+C12*E12+C13*E13)/(C11*$B$5+C12*$D$5+C13*$F$5),0) -> 0.64852941 | G14: =IFERROR((C11*G11+C12*G12+C13*G13)/C14,0) -> 20.1 | H14: =IFERROR((C11*G11+C12*G12+C13*G13)/(C11*($B$5-E11)+C12*($D$5-E12)+C13*($F$5-E13)),0) -> 0.15192744 | I14: =IFERROR((C11*I11+C12*I12+C13*I13)/C14,0) -> 0.2 | J14: =IFERROR(AVERAGEIFS(Object_Log!$V$2:$V$2000,Object_Log!$N$2:$N$2000,"Partner stack",Object_Log!$M$2:$M$2000,"<>Decommission",Object_Log!$P$2:$P$2000,"Y",Object_Log!$U$2:$U$2000,"Y"),0) -> 47.5 | K14: =IFERROR((C11*K11+C12*K12+C13*K13)/C14,0) -> 0.1 | L14: =IFERROR((C11*L11+C12*L12+C13*L13)/C14,0) -> 283 | M14: =IFERROR((C11*M11+C12*M12+C13*M13)/C14,0) -> 41.5
A15: Blended e and q are weighted by baseline minutes (economic weighting) — count-weighting overstates savings when the mix skews simple. Rework is shown per AI-handled unit under 100% senior review.
A17: PANEL B — VANILLA CONTROL & TOOLING UPLIFT (Δ = partner − control; for q/rework/tokens a negative Δ is better)
A18: Class | B18: Units | C18: c — coverage | D18: e — effort reduction | E18: q — QA add-back | F18: Rework rate | G18: Tokens K/unit (in+out) | H18: Δe uplift | I18: Δq | J18: Δ rework | K18: Δ tokens K
A19: Simple | B19: =COUNTIFS(Object_Log!$N$2:$N$2000,"Vanilla control",Object_Log!$M$2:$M$2000,"<>Decommission",Object_Log!$H$2:$H$2000,"Simple") -> 1 | C19: =IFERROR(COUNTIFS(Object_Log!$N$2:$N$2000,"Vanilla control",Object_Log!$M$2:$M$2000,"<>Decommission",Object_Log!$H$2:$H$2000,"Simple",Object_Log!$P$2:$P$2000,"Y")/B19,0) -> 1 | D19: =IFERROR(1-(AVERAGEIFS(Object_Log!$Q$2:$Q$2000,Object_Log!$N$2:$N$2000,"Vanilla control",Object_Log!$M$2:$M$2000,"<>Decommission",Object_Log!$H$2:$H$2000,"Simple",Object_Log!$P$2:$P$2000,"Y")+AVERAGEIFS(Object_Log!$R$2:$R$2000,Object_Log!$N$2:$N$2000,"Vanilla control",Object_Log!$M$2:$M$2000,"<>Decommission",Object_Log!$H$2:$H$2000,"Simple",Object_Log!$P$2:$P$2000,"Y"))/$B$5,0) -> 0.58888889 | E19: =IFERROR(AVERAGEIFS(Object_Log!$S$2:$S$2000,Object_Log!$N$2:$N$2000,"Vanilla control",Object_Log!$M$2:$M$2000,"<>Decommission",Object_Log!$H$2:$H$2000,"Simple",Object_Log!$P$2:$P$2000,"Y")/($B$5-(AVERAGEIFS(Object_Log!$Q$2:$Q$2000,Object_Log!$N$2:$N$2000,"Vanilla control",Object_Log!$M$2:$M$2000,"<>Decommission",Object_Log!$H$2:$H$2000,"Simple",Object_Log!$P$2:$P$2000,"Y")+AVERAGEIFS(Object_Log!$R$2:$R$2000,Object_Log!$N$2:$N$2000,"Vanilla control",Object_Log!$M$2:$M$2000,"<>Decommission",Object_Log!$H$2:$H$2000,"Simple",Object_Log!$P$2:$P$2000,"Y"))),0) -> 0.26415094 | F19: =IFERROR(COUNTIFS(Object_Log!$N$2:$N$2000,"Vanilla control",Object_Log!$M$2:$M$2000,"<>Decommission",Object_Log!$H$2:$H$2000,"Simple",Object_Log!$P$2:$P$2000,"Y",Object_Log!$U$2:$U$2000,"Y")/COUNTIFS(Object_Log!$N$2:$N$2000,"Vanilla control",Object_Log!$M$2:$M$2000,"<>Decommission",Object_Log!$H$2:$H$2000,"Simple",Object_Log!$P$2:$P$2000,"Y"),0) -> 0 | G19: =IFERROR(AVERAGEIFS(Object_Log!$AI$2:$AI$2000,Object_Log!$N$2:$N$2000,"Vanilla control",Object_Log!$M$2:$M$2000,"<>Decommission",Object_Log!$H$2:$H$2000,"Simple",Object_Log!$P$2:$P$2000,"Y")+AVERAGEIFS(Object_Log!$AJ$2:$AJ$2000,Object_Log!$N$2:$N$2000,"Vanilla control",Object_Log!$M$2:$M$2000,"<>Decommission",Object_Log!$H$2:$H$2000,"Simple",Object_Log!$P$2:$P$2000,"Y"),0) -> 298 | H19: =IF(B19=0,"—",F11-D19) -> 0.16944444 | I19: =IF(B19=0,"—",H11-E19) -> -0.15426083 | J19: =IF(B19=0,"—",I11-F19) -> 0.25 | K19: =IF(B19=0,"—",(L11+M11)-G19) -> -86.75
A20: Medium | B20: =COUNTIFS(Object_Log!$N$2:$N$2000,"Vanilla control",Object_Log!$M$2:$M$2000,"<>Decommission",Object_Log!$H$2:$H$2000,"Medium") -> 1 | C20: =IFERROR(COUNTIFS(Object_Log!$N$2:$N$2000,"Vanilla control",Object_Log!$M$2:$M$2000,"<>Decommission",Object_Log!$H$2:$H$2000,"Medium",Object_Log!$P$2:$P$2000,"Y")/B20,0) -> 1 | D20: =IFERROR(1-(AVERAGEIFS(Object_Log!$Q$2:$Q$2000,Object_Log!$N$2:$N$2000,"Vanilla control",Object_Log!$M$2:$M$2000,"<>Decommission",Object_Log!$H$2:$H$2000,"Medium",Object_Log!$P$2:$P$2000,"Y")+AVERAGEIFS(Object_Log!$R$2:$R$2000,Object_Log!$N$2:$N$2000,"Vanilla control",Object_Log!$M$2:$M$2000,"<>Decommission",Object_Log!$H$2:$H$2000,"Medium",Object_Log!$P$2:$P$2000,"Y"))/$D$5,0) -> 0.47142857 | E20: =IFERROR(AVERAGEIFS(Object_Log!$S$2:$S$2000,Object_Log!$N$2:$N$2000,"Vanilla control",Object_Log!$M$2:$M$2000,"<>Decommission",Object_Log!$H$2:$H$2000,"Medium",Object_Log!$P$2:$P$2000,"Y")/($D$5-(AVERAGEIFS(Object_Log!$Q$2:$Q$2000,Object_Log!$N$2:$N$2000,"Vanilla control",Object_Log!$M$2:$M$2000,"<>Decommission",Object_Log!$H$2:$H$2000,"Medium",Object_Log!$P$2:$P$2000,"Y")+AVERAGEIFS(Object_Log!$R$2:$R$2000,Object_Log!$N$2:$N$2000,"Vanilla control",Object_Log!$M$2:$M$2000,"<>Decommission",Object_Log!$H$2:$H$2000,"Medium",Object_Log!$P$2:$P$2000,"Y"))),0) -> 0.3030303 | F20: =IFERROR(COUNTIFS(Object_Log!$N$2:$N$2000,"Vanilla control",Object_Log!$M$2:$M$2000,"<>Decommission",Object_Log!$H$2:$H$2000,"Medium",Object_Log!$P$2:$P$2000,"Y",Object_Log!$U$2:$U$2000,"Y")/COUNTIFS(Object_Log!$N$2:$N$2000,"Vanilla control",Object_Log!$M$2:$M$2000,"<>Decommission",Object_Log!$H$2:$H$2000,"Medium",Object_Log!$P$2:$P$2000,"Y"),0) -> 1 | G20: =IFERROR(AVERAGEIFS(Object_Log!$AI$2:$AI$2000,Object_Log!$N$2:$N$2000,"Vanilla control",Object_Log!$M$2:$M$2000,"<>Decommission",Object_Log!$H$2:$H$2000,"Medium",Object_Log!$P$2:$P$2000,"Y")+AVERAGEIFS(Object_Log!$AJ$2:$AJ$2000,Object_Log!$N$2:$N$2000,"Vanilla control",Object_Log!$M$2:$M$2000,"<>Decommission",Object_Log!$H$2:$H$2000,"Medium",Object_Log!$P$2:$P$2000,"Y"),0) -> 345 | H20: =IF(B20=0,"—",F12-D20) -> 0.20119048 | I20: =IF(B20=0,"—",H12-E20) -> -0.16851703 | J20: =IF(B20=0,"—",I12-F20) -> -0.75 | K20: =IF(B20=0,"—",(L12+M12)-G20) -> -56.25
A21: Complex | B21: =COUNTIFS(Object_Log!$N$2:$N$2000,"Vanilla control",Object_Log!$M$2:$M$2000,"<>Decommission",Object_Log!$H$2:$H$2000,"Complex") -> 1 | C21: =IFERROR(COUNTIFS(Object_Log!$N$2:$N$2000,"Vanilla control",Object_Log!$M$2:$M$2000,"<>Decommission",Object_Log!$H$2:$H$2000,"Complex",Object_Log!$P$2:$P$2000,"Y")/B21,0) -> 1 | D21: =IFERROR(1-(AVERAGEIFS(Object_Log!$Q$2:$Q$2000,Object_Log!$N$2:$N$2000,"Vanilla control",Object_Log!$M$2:$M$2000,"<>Decommission",Object_Log!$H$2:$H$2000,"Complex",Object_Log!$P$2:$P$2000,"Y")+AVERAGEIFS(Object_Log!$R$2:$R$2000,Object_Log!$N$2:$N$2000,"Vanilla control",Object_Log!$M$2:$M$2000,"<>Decommission",Object_Log!$H$2:$H$2000,"Complex",Object_Log!$P$2:$P$2000,"Y"))/$F$5,0) -> 0.3452381 | E21: =IFERROR(AVERAGEIFS(Object_Log!$S$2:$S$2000,Object_Log!$N$2:$N$2000,"Vanilla control",Object_Log!$M$2:$M$2000,"<>Decommission",Object_Log!$H$2:$H$2000,"Complex",Object_Log!$P$2:$P$2000,"Y")/($F$5-(AVERAGEIFS(Object_Log!$Q$2:$Q$2000,Object_Log!$N$2:$N$2000,"Vanilla control",Object_Log!$M$2:$M$2000,"<>Decommission",Object_Log!$H$2:$H$2000,"Complex",Object_Log!$P$2:$P$2000,"Y")+AVERAGEIFS(Object_Log!$R$2:$R$2000,Object_Log!$N$2:$N$2000,"Vanilla control",Object_Log!$M$2:$M$2000,"<>Decommission",Object_Log!$H$2:$H$2000,"Complex",Object_Log!$P$2:$P$2000,"Y"))),0) -> 0.48275862 | F21: =IFERROR(COUNTIFS(Object_Log!$N$2:$N$2000,"Vanilla control",Object_Log!$M$2:$M$2000,"<>Decommission",Object_Log!$H$2:$H$2000,"Complex",Object_Log!$P$2:$P$2000,"Y",Object_Log!$U$2:$U$2000,"Y")/COUNTIFS(Object_Log!$N$2:$N$2000,"Vanilla control",Object_Log!$M$2:$M$2000,"<>Decommission",Object_Log!$H$2:$H$2000,"Complex",Object_Log!$P$2:$P$2000,"Y"),0) -> 0 | G21: =IFERROR(AVERAGEIFS(Object_Log!$AI$2:$AI$2000,Object_Log!$N$2:$N$2000,"Vanilla control",Object_Log!$M$2:$M$2000,"<>Decommission",Object_Log!$H$2:$H$2000,"Complex",Object_Log!$P$2:$P$2000,"Y")+AVERAGEIFS(Object_Log!$AJ$2:$AJ$2000,Object_Log!$N$2:$N$2000,"Vanilla control",Object_Log!$M$2:$M$2000,"<>Decommission",Object_Log!$H$2:$H$2000,"Complex",Object_Log!$P$2:$P$2000,"Y"),0) -> 810 | H21: =IF(B21=0,"—",F13-D21) -> 0.23214286 | I21: =IF(B21=0,"—",H13-E21) -> -0.28688233 | J21: =IF(B21=0,"—",I13-F21) -> 0 | K21: =IF(B21=0,"—",(L13+M13)-G21) -> -187.5
A22: Control protocol: deliver a matched sample (~30–50 units mirroring the class mix) with the same model tier, generic prompting, no accelerators. The Δ columns are the measured value of the partner toolchain — the evidence behind any platform-IP or licensing claim.
A24: PANEL C — CURRENT CONFIG VERSION ONLY · PARTNER STACK (feeds the calculator)
A25: Class | B25: Fresh units | C25: c — coverage | D25: e — effort reduction | E25: q — QA add-back | F25: Rework rate | G25: Avg rework min | H25: Warranty claim rate | I25: Tokens in K/unit | J25: Tokens out K/unit | K25: Status
A26: Simple | B26: =COUNTIFS(Object_Log!$N$2:$N$2000,"Partner stack",Object_Log!$M$2:$M$2000,"<>Decommission",Object_Log!$AF$2:$AF$2000,$B$7,Object_Log!$H$2:$H$2000,"Simple") -> 4 | C26: =IFERROR(COUNTIFS(Object_Log!$N$2:$N$2000,"Partner stack",Object_Log!$M$2:$M$2000,"<>Decommission",Object_Log!$AF$2:$AF$2000,$B$7,Object_Log!$H$2:$H$2000,"Simple",Object_Log!$P$2:$P$2000,"Y")/B26,0) -> 1 | D26: =IFERROR(1-(AVERAGEIFS(Object_Log!$Q$2:$Q$2000,Object_Log!$N$2:$N$2000,"Partner stack",Object_Log!$M$2:$M$2000,"<>Decommission",Object_Log!$AF$2:$AF$2000,$B$7,Object_Log!$H$2:$H$2000,"Simple",Object_Log!$P$2:$P$2000,"Y")+AVERAGEIFS(Object_Log!$R$2:$R$2000,Object_Log!$N$2:$N$2000,"Partner stack",Object_Log!$M$2:$M$2000,"<>Decommission",Object_Log!$AF$2:$AF$2000,$B$7,Object_Log!$H$2:$H$2000,"Simple",Object_Log!$P$2:$P$2000,"Y"))/$B$5,0) -> 0.75833333 | E26: =IFERROR(AVERAGEIFS(Object_Log!$S$2:$S$2000,Object_Log!$N$2:$N$2000,"Partner stack",Object_Log!$M$2:$M$2000,"<>Decommission",Object_Log!$AF$2:$AF$2000,$B$7,Object_Log!$H$2:$H$2000,"Simple",Object_Log!$P$2:$P$2000,"Y")/($B$5-(AVERAGEIFS(Object_Log!$Q$2:$Q$2000,Object_Log!$N$2:$N$2000,"Partner stack",Object_Log!$M$2:$M$2000,"<>Decommission",Object_Log!$AF$2:$AF$2000,$B$7,Object_Log!$H$2:$H$2000,"Simple",Object_Log!$P$2:$P$2000,"Y")+AVERAGEIFS(Object_Log!$R$2:$R$2000,Object_Log!$N$2:$N$2000,"Partner stack",Object_Log!$M$2:$M$2000,"<>Decommission",Object_Log!$AF$2:$AF$2000,$B$7,Object_Log!$H$2:$H$2000,"Simple",Object_Log!$P$2:$P$2000,"Y"))),0) -> 0.10989011 | F26: =IFERROR(COUNTIFS(Object_Log!$N$2:$N$2000,"Partner stack",Object_Log!$M$2:$M$2000,"<>Decommission",Object_Log!$AF$2:$AF$2000,$B$7,Object_Log!$H$2:$H$2000,"Simple",Object_Log!$P$2:$P$2000,"Y",Object_Log!$U$2:$U$2000,"Y")/COUNTIFS(Object_Log!$N$2:$N$2000,"Partner stack",Object_Log!$M$2:$M$2000,"<>Decommission",Object_Log!$AF$2:$AF$2000,$B$7,Object_Log!$H$2:$H$2000,"Simple",Object_Log!$P$2:$P$2000,"Y"),0) -> 0.25 | G26: =IFERROR(AVERAGEIFS(Object_Log!$V$2:$V$2000,Object_Log!$N$2:$N$2000,"Partner stack",Object_Log!$M$2:$M$2000,"<>Decommission",Object_Log!$AF$2:$AF$2000,$B$7,Object_Log!$H$2:$H$2000,"Simple",Object_Log!$P$2:$P$2000,"Y",Object_Log!$U$2:$U$2000,"Y"),0) -> 35 | H26: =IFERROR(COUNTIFS(Object_Log!$N$2:$N$2000,"Partner stack",Object_Log!$M$2:$M$2000,"<>Decommission",Object_Log!$AF$2:$AF$2000,$B$7,Object_Log!$H$2:$H$2000,"Simple",Object_Log!$P$2:$P$2000,"Y",Object_Log!$Y$2:$Y$2000,"Y")/COUNTIFS(Object_Log!$N$2:$N$2000,"Partner stack",Object_Log!$M$2:$M$2000,"<>Decommission",Object_Log!$AF$2:$AF$2000,$B$7,Object_Log!$H$2:$H$2000,"Simple",Object_Log!$P$2:$P$2000,"Y"),0) -> 0 | I26: =IFERROR(AVERAGEIFS(Object_Log!$AI$2:$AI$2000,Object_Log!$N$2:$N$2000,"Partner stack",Object_Log!$M$2:$M$2000,"<>Decommission",Object_Log!$AF$2:$AF$2000,$B$7,Object_Log!$H$2:$H$2000,"Simple",Object_Log!$P$2:$P$2000,"Y"),0) -> 185 | J26: =IFERROR(AVERAGEIFS(Object_Log!$AJ$2:$AJ$2000,Object_Log!$N$2:$N$2000,"Partner stack",Object_Log!$M$2:$M$2000,"<>Decommission",Object_Log!$AF$2:$AF$2000,$B$7,Object_Log!$H$2:$H$2000,"Simple",Object_Log!$P$2:$P$2000,"Y"),0) -> 26.25 | K26: =IF(B26>=$D$7,"OK","LOW n="&B26) -> LOW n=4
A27: Medium | B27: =COUNTIFS(Object_Log!$N$2:$N$2000,"Partner stack",Object_Log!$M$2:$M$2000,"<>Decommission",Object_Log!$AF$2:$AF$2000,$B$7,Object_Log!$H$2:$H$2000,"Medium") -> 4 | C27: =IFERROR(COUNTIFS(Object_Log!$N$2:$N$2000,"Partner stack",Object_Log!$M$2:$M$2000,"<>Decommission",Object_Log!$AF$2:$AF$2000,$B$7,Object_Log!$H$2:$H$2000,"Medium",Object_Log!$P$2:$P$2000,"Y")/B27,0) -> 1 | D27: =IFERROR(1-(AVERAGEIFS(Object_Log!$Q$2:$Q$2000,Object_Log!$N$2:$N$2000,"Partner stack",Object_Log!$M$2:$M$2000,"<>Decommission",Object_Log!$AF$2:$AF$2000,$B$7,Object_Log!$H$2:$H$2000,"Medium",Object_Log!$P$2:$P$2000,"Y")+AVERAGEIFS(Object_Log!$R$2:$R$2000,Object_Log!$N$2:$N$2000,"Partner stack",Object_Log!$M$2:$M$2000,"<>Decommission",Object_Log!$AF$2:$AF$2000,$B$7,Object_Log!$H$2:$H$2000,"Medium",Object_Log!$P$2:$P$2000,"Y"))/$D$5,0) -> 0.67261905 | E27: =IFERROR(AVERAGEIFS(Object_Log!$S$2:$S$2000,Object_Log!$N$2:$N$2000,"Partner stack",Object_Log!$M$2:$M$2000,"<>Decommission",Object_Log!$AF$2:$AF$2000,$B$7,Object_Log!$H$2:$H$2000,"Medium",Object_Log!$P$2:$P$2000,"Y")/($D$5-(AVERAGEIFS(Object_Log!$Q$2:$Q$2000,Object_Log!$N$2:$N$2000,"Partner stack",Object_Log!$M$2:$M$2000,"<>Decommission",Object_Log!$AF$2:$AF$2000,$B$7,Object_Log!$H$2:$H$2000,"Medium",Object_Log!$P$2:$P$2000,"Y")+AVERAGEIFS(Object_Log!$R$2:$R$2000,Object_Log!$N$2:$N$2000,"Partner stack",Object_Log!$M$2:$M$2000,"<>Decommission",Object_Log!$AF$2:$AF$2000,$B$7,Object_Log!$H$2:$H$2000,"Medium",Object_Log!$P$2:$P$2000,"Y"))),0) -> 0.13451327 | F27: =IFERROR(COUNTIFS(Object_Log!$N$2:$N$2000,"Partner stack",Object_Log!$M$2:$M$2000,"<>Decommission",Object_Log!$AF$2:$AF$2000,$B$7,Object_Log!$H$2:$H$2000,"Medium",Object_Log!$P$2:$P$2000,"Y",Object_Log!$U$2:$U$2000,"Y")/COUNTIFS(Object_Log!$N$2:$N$2000,"Partner stack",Object_Log!$M$2:$M$2000,"<>Decommission",Object_Log!$AF$2:$AF$2000,$B$7,Object_Log!$H$2:$H$2000,"Medium",Object_Log!$P$2:$P$2000,"Y"),0) -> 0.25 | G27: =IFERROR(AVERAGEIFS(Object_Log!$V$2:$V$2000,Object_Log!$N$2:$N$2000,"Partner stack",Object_Log!$M$2:$M$2000,"<>Decommission",Object_Log!$AF$2:$AF$2000,$B$7,Object_Log!$H$2:$H$2000,"Medium",Object_Log!$P$2:$P$2000,"Y",Object_Log!$U$2:$U$2000,"Y"),0) -> 60 | H27: =IFERROR(COUNTIFS(Object_Log!$N$2:$N$2000,"Partner stack",Object_Log!$M$2:$M$2000,"<>Decommission",Object_Log!$AF$2:$AF$2000,$B$7,Object_Log!$H$2:$H$2000,"Medium",Object_Log!$P$2:$P$2000,"Y",Object_Log!$Y$2:$Y$2000,"Y")/COUNTIFS(Object_Log!$N$2:$N$2000,"Partner stack",Object_Log!$M$2:$M$2000,"<>Decommission",Object_Log!$AF$2:$AF$2000,$B$7,Object_Log!$H$2:$H$2000,"Medium",Object_Log!$P$2:$P$2000,"Y"),0) -> 0.25 | I27: =IFERROR(AVERAGEIFS(Object_Log!$AI$2:$AI$2000,Object_Log!$N$2:$N$2000,"Partner stack",Object_Log!$M$2:$M$2000,"<>Decommission",Object_Log!$AF$2:$AF$2000,$B$7,Object_Log!$H$2:$H$2000,"Medium",Object_Log!$P$2:$P$2000,"Y"),0) -> 252.5 | J27: =IFERROR(AVERAGEIFS(Object_Log!$AJ$2:$AJ$2000,Object_Log!$N$2:$N$2000,"Partner stack",Object_Log!$M$2:$M$2000,"<>Decommission",Object_Log!$AF$2:$AF$2000,$B$7,Object_Log!$H$2:$H$2000,"Medium",Object_Log!$P$2:$P$2000,"Y"),0) -> 36.25 | K27: =IF(B27>=$D$7,"OK","LOW n="&B27) -> LOW n=4
A28: Complex | B28: =COUNTIFS(Object_Log!$N$2:$N$2000,"Partner stack",Object_Log!$M$2:$M$2000,"<>Decommission",Object_Log!$AF$2:$AF$2000,$B$7,Object_Log!$H$2:$H$2000,"Complex") -> 4 | C28: =IFERROR(COUNTIFS(Object_Log!$N$2:$N$2000,"Partner stack",Object_Log!$M$2:$M$2000,"<>Decommission",Object_Log!$AF$2:$AF$2000,$B$7,Object_Log!$H$2:$H$2000,"Complex",Object_Log!$P$2:$P$2000,"Y")/B28,0) -> 0.5 | D28: =IFERROR(1-(AVERAGEIFS(Object_Log!$Q$2:$Q$2000,Object_Log!$N$2:$N$2000,"Partner stack",Object_Log!$M$2:$M$2000,"<>Decommission",Object_Log!$AF$2:$AF$2000,$B$7,Object_Log!$H$2:$H$2000,"Complex",Object_Log!$P$2:$P$2000,"Y")+AVERAGEIFS(Object_Log!$R$2:$R$2000,Object_Log!$N$2:$N$2000,"Partner stack",Object_Log!$M$2:$M$2000,"<>Decommission",Object_Log!$AF$2:$AF$2000,$B$7,Object_Log!$H$2:$H$2000,"Complex",Object_Log!$P$2:$P$2000,"Y"))/$F$5,0) -> 0.57738095 | E28: =IFERROR(AVERAGEIFS(Object_Log!$S$2:$S$2000,Object_Log!$N$2:$N$2000,"Partner stack",Object_Log!$M$2:$M$2000,"<>Decommission",Object_Log!$AF$2:$AF$2000,$B$7,Object_Log!$H$2:$H$2000,"Complex",Object_Log!$P$2:$P$2000,"Y")/($F$5-(AVERAGEIFS(Object_Log!$Q$2:$Q$2000,Object_Log!$N$2:$N$2000,"Partner stack",Object_Log!$M$2:$M$2000,"<>Decommission",Object_Log!$AF$2:$AF$2000,$B$7,Object_Log!$H$2:$H$2000,"Complex",Object_Log!$P$2:$P$2000,"Y")+AVERAGEIFS(Object_Log!$R$2:$R$2000,Object_Log!$N$2:$N$2000,"Partner stack",Object_Log!$M$2:$M$2000,"<>Decommission",Object_Log!$AF$2:$AF$2000,$B$7,Object_Log!$H$2:$H$2000,"Complex",Object_Log!$P$2:$P$2000,"Y"))),0) -> 0.19587629 | F28: =IFERROR(COUNTIFS(Object_Log!$N$2:$N$2000,"Partner stack",Object_Log!$M$2:$M$2000,"<>Decommission",Object_Log!$AF$2:$AF$2000,$B$7,Object_Log!$H$2:$H$2000,"Complex",Object_Log!$P$2:$P$2000,"Y",Object_Log!$U$2:$U$2000,"Y")/COUNTIFS(Object_Log!$N$2:$N$2000,"Partner stack",Object_Log!$M$2:$M$2000,"<>Decommission",Object_Log!$AF$2:$AF$2000,$B$7,Object_Log!$H$2:$H$2000,"Complex",Object_Log!$P$2:$P$2000,"Y"),0) -> 0 | G28: =IFERROR(AVERAGEIFS(Object_Log!$V$2:$V$2000,Object_Log!$N$2:$N$2000,"Partner stack",Object_Log!$M$2:$M$2000,"<>Decommission",Object_Log!$AF$2:$AF$2000,$B$7,Object_Log!$H$2:$H$2000,"Complex",Object_Log!$P$2:$P$2000,"Y",Object_Log!$U$2:$U$2000,"Y"),0) -> 0 | H28: =IFERROR(COUNTIFS(Object_Log!$N$2:$N$2000,"Partner stack",Object_Log!$M$2:$M$2000,"<>Decommission",Object_Log!$AF$2:$AF$2000,$B$7,Object_Log!$H$2:$H$2000,"Complex",Object_Log!$P$2:$P$2000,"Y",Object_Log!$Y$2:$Y$2000,"Y")/COUNTIFS(Object_Log!$N$2:$N$2000,"Partner stack",Object_Log!$M$2:$M$2000,"<>Decommission",Object_Log!$AF$2:$AF$2000,$B$7,Object_Log!$H$2:$H$2000,"Complex",Object_Log!$P$2:$P$2000,"Y"),0) -> 0 | I28: =IFERROR(AVERAGEIFS(Object_Log!$AI$2:$AI$2000,Object_Log!$N$2:$N$2000,"Partner stack",Object_Log!$M$2:$M$2000,"<>Decommission",Object_Log!$AF$2:$AF$2000,$B$7,Object_Log!$H$2:$H$2000,"Complex",Object_Log!$P$2:$P$2000,"Y"),0) -> 540 | J28: =IFERROR(AVERAGEIFS(Object_Log!$AJ$2:$AJ$2000,Object_Log!$N$2:$N$2000,"Partner stack",Object_Log!$M$2:$M$2000,"<>Decommission",Object_Log!$AF$2:$AF$2000,$B$7,Object_Log!$H$2:$H$2000,"Complex",Object_Log!$P$2:$P$2000,"Y"),0) -> 82.5 | K28: =IF(B28>=$D$7,"OK","LOW n="&B28) -> LOW n=4
A29: BLENDED (minute-weighted) | B29: =SUM(B26:B28) -> 12 | C29: =IFERROR((COUNTIFS(Object_Log!$N$2:$N$2000,"Partner stack",Object_Log!$M$2:$M$2000,"<>Decommission",Object_Log!$AF$2:$AF$2000,$B$7,Object_Log!$H$2:$H$2000,"Simple",Object_Log!$P$2:$P$2000,"Y")+COUNTIFS(Object_Log!$N$2:$N$2000,"Partner stack",Object_Log!$M$2:$M$2000,"<>Decommission",Object_Log!$AF$2:$AF$2000,$B$7,Object_Log!$H$2:$H$2000,"Medium",Object_Log!$P$2:$P$2000,"Y")+COUNTIFS(Object_Log!$N$2:$N$2000,"Partner stack",Object_Log!$M$2:$M$2000,"<>Decommission",Object_Log!$AF$2:$AF$2000,$B$7,Object_Log!$H$2:$H$2000,"Complex",Object_Log!$P$2:$P$2000,"Y"))/B29,0) -> 0.83333333 | D29: =IFERROR(1-(COUNTIFS(Object_Log!$N$2:$N$2000,"Partner stack",Object_Log!$M$2:$M$2000,"<>Decommission",Object_Log!$AF$2:$AF$2000,$B$7,Object_Log!$H$2:$H$2000,"Simple",Object_Log!$P$2:$P$2000,"Y")*($B$5*(1-D26))+COUNTIFS(Object_Log!$N$2:$N$2000,"Partner stack",Object_Log!$M$2:$M$2000,"<>Decommission",Object_Log!$AF$2:$AF$2000,$B$7,Object_Log!$H$2:$H$2000,"Medium",Object_Log!$P$2:$P$2000,"Y")*($D$5*(1-D27))+COUNTIFS(Object_Log!$N$2:$N$2000,"Partner stack",Object_Log!$M$2:$M$2000,"<>Decommission",Object_Log!$AF$2:$AF$2000,$B$7,Object_Log!$H$2:$H$2000,"Complex",Object_Log!$P$2:$P$2000,"Y")*($F$5*(1-D28)))/(COUNTIFS(Object_Log!$N$2:$N$2000,"Partner stack",Object_Log!$M$2:$M$2000,"<>Decommission",Object_Log!$AF$2:$AF$2000,$B$7,Object_Log!$H$2:$H$2000,"Simple",Object_Log!$P$2:$P$2000,"Y")*$B$5+COUNTIFS(Object_Log!$N$2:$N$2000,"Partner stack",Object_Log!$M$2:$M$2000,"<>Decommission",Object_Log!$AF$2:$AF$2000,$B$7,Object_Log!$H$2:$H$2000,"Medium",Object_Log!$P$2:$P$2000,"Y")*$D$5+COUNTIFS(Object_Log!$N$2:$N$2000,"Partner stack",Object_Log!$M$2:$M$2000,"<>Decommission",Object_Log!$AF$2:$AF$2000,$B$7,Object_Log!$H$2:$H$2000,"Complex",Object_Log!$P$2:$P$2000,"Y")*$F$5),0) -> 0.64852941 | E29: =IFERROR((COUNTIFS(Object_Log!$N$2:$N$2000,"Partner stack",Object_Log!$M$2:$M$2000,"<>Decommission",Object_Log!$AF$2:$AF$2000,$B$7,Object_Log!$H$2:$H$2000,"Simple",Object_Log!$P$2:$P$2000,"Y")*E26*$B$5*D26+COUNTIFS(Object_Log!$N$2:$N$2000,"Partner stack",Object_Log!$M$2:$M$2000,"<>Decommission",Object_Log!$AF$2:$AF$2000,$B$7,Object_Log!$H$2:$H$2000,"Medium",Object_Log!$P$2:$P$2000,"Y")*E27*$D$5*D27+COUNTIFS(Object_Log!$N$2:$N$2000,"Partner stack",Object_Log!$M$2:$M$2000,"<>Decommission",Object_Log!$AF$2:$AF$2000,$B$7,Object_Log!$H$2:$H$2000,"Complex",Object_Log!$P$2:$P$2000,"Y")*E28*$F$5*D28)/(COUNTIFS(Object_Log!$N$2:$N$2000,"Partner stack",Object_Log!$M$2:$M$2000,"<>Decommission",Object_Log!$AF$2:$AF$2000,$B$7,Object_Log!$H$2:$H$2000,"Simple",Object_Log!$P$2:$P$2000,"Y")*$B$5*D26+COUNTIFS(Object_Log!$N$2:$N$2000,"Partner stack",Object_Log!$M$2:$M$2000,"<>Decommission",Object_Log!$AF$2:$AF$2000,$B$7,Object_Log!$H$2:$H$2000,"Medium",Object_Log!$P$2:$P$2000,"Y")*$D$5*D27+COUNTIFS(Object_Log!$N$2:$N$2000,"Partner stack",Object_Log!$M$2:$M$2000,"<>Decommission",Object_Log!$AF$2:$AF$2000,$B$7,Object_Log!$H$2:$H$2000,"Complex",Object_Log!$P$2:$P$2000,"Y")*$F$5*D28),0) -> 0.15192744 | F29: =IFERROR((COUNTIFS(Object_Log!$N$2:$N$2000,"Partner stack",Object_Log!$M$2:$M$2000,"<>Decommission",Object_Log!$AF$2:$AF$2000,$B$7,Object_Log!$H$2:$H$2000,"Simple",Object_Log!$P$2:$P$2000,"Y")*F26+COUNTIFS(Object_Log!$N$2:$N$2000,"Partner stack",Object_Log!$M$2:$M$2000,"<>Decommission",Object_Log!$AF$2:$AF$2000,$B$7,Object_Log!$H$2:$H$2000,"Medium",Object_Log!$P$2:$P$2000,"Y")*F27+COUNTIFS(Object_Log!$N$2:$N$2000,"Partner stack",Object_Log!$M$2:$M$2000,"<>Decommission",Object_Log!$AF$2:$AF$2000,$B$7,Object_Log!$H$2:$H$2000,"Complex",Object_Log!$P$2:$P$2000,"Y")*F28)/(COUNTIFS(Object_Log!$N$2:$N$2000,"Partner stack",Object_Log!$M$2:$M$2000,"<>Decommission",Object_Log!$AF$2:$AF$2000,$B$7,Object_Log!$H$2:$H$2000,"Simple",Object_Log!$P$2:$P$2000,"Y")+COUNTIFS(Object_Log!$N$2:$N$2000,"Partner stack",Object_Log!$M$2:$M$2000,"<>Decommission",Object_Log!$AF$2:$AF$2000,$B$7,Object_Log!$H$2:$H$2000,"Medium",Object_Log!$P$2:$P$2000,"Y")+COUNTIFS(Object_Log!$N$2:$N$2000,"Partner stack",Object_Log!$M$2:$M$2000,"<>Decommission",Object_Log!$AF$2:$AF$2000,$B$7,Object_Log!$H$2:$H$2000,"Complex",Object_Log!$P$2:$P$2000,"Y")),0) -> 0.2 | G29: =IFERROR(AVERAGEIFS(Object_Log!$V$2:$V$2000,Object_Log!$N$2:$N$2000,"Partner stack",Object_Log!$M$2:$M$2000,"<>Decommission",Object_Log!$AF$2:$AF$2000,$B$7,Object_Log!$P$2:$P$2000,"Y",Object_Log!$U$2:$U$2000,"Y"),0) -> 47.5 | H29: =IFERROR((COUNTIFS(Object_Log!$N$2:$N$2000,"Partner stack",Object_Log!$M$2:$M$2000,"<>Decommission",Object_Log!$AF$2:$AF$2000,$B$7,Object_Log!$H$2:$H$2000,"Simple",Object_Log!$P$2:$P$2000,"Y")*H26+COUNTIFS(Object_Log!$N$2:$N$2000,"Partner stack",Object_Log!$M$2:$M$2000,"<>Decommission",Object_Log!$AF$2:$AF$2000,$B$7,Object_Log!$H$2:$H$2000,"Medium",Object_Log!$P$2:$P$2000,"Y")*H27+COUNTIFS(Object_Log!$N$2:$N$2000,"Partner stack",Object_Log!$M$2:$M$2000,"<>Decommission",Object_Log!$AF$2:$AF$2000,$B$7,Object_Log!$H$2:$H$2000,"Complex",Object_Log!$P$2:$P$2000,"Y")*H28)/(COUNTIFS(Object_Log!$N$2:$N$2000,"Partner stack",Object_Log!$M$2:$M$2000,"<>Decommission",Object_Log!$AF$2:$AF$2000,$B$7,Object_Log!$H$2:$H$2000,"Simple",Object_Log!$P$2:$P$2000,"Y")+COUNTIFS(Object_Log!$N$2:$N$2000,"Partner stack",Object_Log!$M$2:$M$2000,"<>Decommission",Object_Log!$AF$2:$AF$2000,$B$7,Object_Log!$H$2:$H$2000,"Medium",Object_Log!$P$2:$P$2000,"Y")+COUNTIFS(Object_Log!$N$2:$N$2000,"Partner stack",Object_Log!$M$2:$M$2000,"<>Decommission",Object_Log!$AF$2:$AF$2000,$B$7,Object_Log!$H$2:$H$2000,"Complex",Object_Log!$P$2:$P$2000,"Y")),0) -> 0.1 | I29: =IFERROR((COUNTIFS(Object_Log!$N$2:$N$2000,"Partner stack",Object_Log!$M$2:$M$2000,"<>Decommission",Object_Log!$AF$2:$AF$2000,$B$7,Object_Log!$H$2:$H$2000,"Simple",Object_Log!$P$2:$P$2000,"Y")*I26+COUNTIFS(Object_Log!$N$2:$N$2000,"Partner stack",Object_Log!$M$2:$M$2000,"<>Decommission",Object_Log!$AF$2:$AF$2000,$B$7,Object_Log!$H$2:$H$2000,"Medium",Object_Log!$P$2:$P$2000,"Y")*I27+COUNTIFS(Object_Log!$N$2:$N$2000,"Partner stack",Object_Log!$M$2:$M$2000,"<>Decommission",Object_Log!$AF$2:$AF$2000,$B$7,Object_Log!$H$2:$H$2000,"Complex",Object_Log!$P$2:$P$2000,"Y")*I28)/(COUNTIFS(Object_Log!$N$2:$N$2000,"Partner stack",Object_Log!$M$2:$M$2000,"<>Decommission",Object_Log!$AF$2:$AF$2000,$B$7,Object_Log!$H$2:$H$2000,"Simple",Object_Log!$P$2:$P$2000,"Y")+COUNTIFS(Object_Log!$N$2:$N$2000,"Partner stack",Object_Log!$M$2:$M$2000,"<>Decommission",Object_Log!$AF$2:$AF$2000,$B$7,Object_Log!$H$2:$H$2000,"Medium",Object_Log!$P$2:$P$2000,"Y")+COUNTIFS(Object_Log!$N$2:$N$2000,"Partner stack",Object_Log!$M$2:$M$2000,"<>Decommission",Object_Log!$AF$2:$AF$2000,$B$7,Object_Log!$H$2:$H$2000,"Complex",Object_Log!$P$2:$P$2000,"Y")),0) -> 283 | J29: =IFERROR((COUNTIFS(Object_Log!$N$2:$N$2000,"Partner stack",Object_Log!$M$2:$M$2000,"<>Decommission",Object_Log!$AF$2:$AF$2000,$B$7,Object_Log!$H$2:$H$2000,"Simple",Object_Log!$P$2:$P$2000,"Y")*J26+COUNTIFS(Object_Log!$N$2:$N$2000,"Partner stack",Object_Log!$M$2:$M$2000,"<>Decommission",Object_Log!$AF$2:$AF$2000,$B$7,Object_Log!$H$2:$H$2000,"Medium",Object_Log!$P$2:$P$2000,"Y")*J27+COUNTIFS(Object_Log!$N$2:$N$2000,"Partner stack",Object_Log!$M$2:$M$2000,"<>Decommission",Object_Log!$AF$2:$AF$2000,$B$7,Object_Log!$H$2:$H$2000,"Complex",Object_Log!$P$2:$P$2000,"Y")*J28)/(COUNTIFS(Object_Log!$N$2:$N$2000,"Partner stack",Object_Log!$M$2:$M$2000,"<>Decommission",Object_Log!$AF$2:$AF$2000,$B$7,Object_Log!$H$2:$H$2000,"Simple",Object_Log!$P$2:$P$2000,"Y")+COUNTIFS(Object_Log!$N$2:$N$2000,"Partner stack",Object_Log!$M$2:$M$2000,"<>Decommission",Object_Log!$AF$2:$AF$2000,$B$7,Object_Log!$H$2:$H$2000,"Medium",Object_Log!$P$2:$P$2000,"Y")+COUNTIFS(Object_Log!$N$2:$N$2000,"Partner stack",Object_Log!$M$2:$M$2000,"<>Decommission",Object_Log!$AF$2:$AF$2000,$B$7,Object_Log!$H$2:$H$2000,"Complex",Object_Log!$P$2:$P$2000,"Y")),0) -> 41.5
A31: SCOPE & CLASSIFICATION INTEGRITY
A32: Units reclassified (initial ≠ final) | B32: =SUMPRODUCT((Object_Log!$G$2:$G$2000<>Object_Log!$H$2:$H$2000)*(Object_Log!$A$2:$A$2000<>"")) -> 1 | C32: of which upgraded | D32: =SUMPRODUCT((((Object_Log!$H$2:$H$2000="Simple")*1+(Object_Log!$H$2:$H$2000="Medium")*2+(Object_Log!$H$2:$H$2000="Complex")*3)>((Object_Log!$G$2:$G$2000="Simple")*1+(Object_Log!$G$2:$G$2000="Medium")*2+(Object_Log!$G$2:$G$2000="Complex")*3))*1) -> 1 | E32: Distinct engagements logged | F32: =SUMPRODUCT((Object_Log!$C$2:$C$2000<>"")/(COUNTIF(Object_Log!$C$2:$C$2000,Object_Log!$C$2:$C$2000&"")+(Object_Log!$C$2:$C$2000=""))) -> 1
A33: Decommission share of logged units | B33: =IFERROR(COUNTIFS(Object_Log!$M$2:$M$2000,"Decommission")/COUNTIF(Object_Log!$A$2:$A$2000,"?*"),0) -> 0.0625 | C33: Avg min/decommissioned unit | D33: =IFERROR(AVERAGEIFS(Object_Log!$Q$2:$Q$2000,Object_Log!$M$2:$M$2000,"Decommission")+AVERAGEIFS(Object_Log!$R$2:$R$2000,Object_Log!$M$2:$M$2000,"Decommission"),0) -> 20 | E33: Distinct customers logged | F33: =SUMPRODUCT((Object_Log!$D$2:$D$2000<>"")/(COUNTIF(Object_Log!$D$2:$D$2000,Object_Log!$D$2:$D$2000&"")+(Object_Log!$D$2:$D$2000=""))) -> 1
A34: First-pass acceptance rate (AI-handled) | B34: =IFERROR(COUNTIFS(Object_Log!$P$2:$P$2000,"Y",Object_Log!$T$2:$T$2000,"Y")/COUNTIFS(Object_Log!$P$2:$P$2000,"Y"),0) -> 0.76923077 | C34: AI attempted but abandoned | D34: =COUNTIFS(Object_Log!$O$2:$O$2000,"Y",Object_Log!$P$2:$P$2000,"N") -> 1
A36: VALUES FOR THE PRICING CALCULATOR — current config only, evidence-gated
A37: Parameter | B37: Simple | C37: Medium | D37: Complex | E37: Blended (min-wtd)
A38: AI coverage c | B38: =IF($B$48,C26,"INSUFFICIENT EVIDENCE") -> INSUFFICIENT EVIDENCE | C38: =IF($B$48,C27,"INSUFFICIENT EVIDENCE") -> INSUFFICIENT EVIDENCE | D38: =IF($B$48,C28,"INSUFFICIENT EVIDENCE") -> INSUFFICIENT EVIDENCE | E38: =IF($B$48,C29,"INSUFFICIENT EVIDENCE") -> INSUFFICIENT EVIDENCE
A39: Effort reduction e | B39: =IF($B$48,D26,"INSUFFICIENT EVIDENCE") -> INSUFFICIENT EVIDENCE | C39: =IF($B$48,D27,"INSUFFICIENT EVIDENCE") -> INSUFFICIENT EVIDENCE | D39: =IF($B$48,D28,"INSUFFICIENT EVIDENCE") -> INSUFFICIENT EVIDENCE | E39: =IF($B$48,D29,"INSUFFICIENT EVIDENCE") -> INSUFFICIENT EVIDENCE
A40: QA add-back q | B40: =IF($B$48,E26,"INSUFFICIENT EVIDENCE") -> INSUFFICIENT EVIDENCE | C40: =IF($B$48,E27,"INSUFFICIENT EVIDENCE") -> INSUFFICIENT EVIDENCE | D40: =IF($B$48,E28,"INSUFFICIENT EVIDENCE") -> INSUFFICIENT EVIDENCE | E40: =IF($B$48,E29,"INSUFFICIENT EVIDENCE") -> INSUFFICIENT EVIDENCE
A41: Tokens in per covered unit (K) | B41: =IF($B$48,I26,"INSUFFICIENT EVIDENCE") -> INSUFFICIENT EVIDENCE | C41: =IF($B$48,I27,"INSUFFICIENT EVIDENCE") -> INSUFFICIENT EVIDENCE | D41: =IF($B$48,I28,"INSUFFICIENT EVIDENCE") -> INSUFFICIENT EVIDENCE | E41: =IF($B$48,I29,"INSUFFICIENT EVIDENCE") -> INSUFFICIENT EVIDENCE
A42: Tokens out per covered unit (K) | B42: =IF($B$48,J26,"INSUFFICIENT EVIDENCE") -> INSUFFICIENT EVIDENCE | C42: =IF($B$48,J27,"INSUFFICIENT EVIDENCE") -> INSUFFICIENT EVIDENCE | D42: =IF($B$48,J28,"INSUFFICIENT EVIDENCE") -> INSUFFICIENT EVIDENCE | E42: =IF($B$48,J29,"INSUFFICIENT EVIDENCE") -> INSUFFICIENT EVIDENCE
A43: Rework rate (100% senior review until sustained < target) | B43: =IF($B$48,F26,"INSUFFICIENT EVIDENCE") -> INSUFFICIENT EVIDENCE | C43: =IF($B$48,F27,"INSUFFICIENT EVIDENCE") -> INSUFFICIENT EVIDENCE | D43: =IF($B$48,F28,"INSUFFICIENT EVIDENCE") -> INSUFFICIENT EVIDENCE | E43: =IF($B$48,F29,"INSUFFICIENT EVIDENCE") -> INSUFFICIENT EVIDENCE
A44: Avg rework minutes per reworked unit | B44: =IF($B$48,G26,"INSUFFICIENT EVIDENCE") -> INSUFFICIENT EVIDENCE | C44: =IF($B$48,G27,"INSUFFICIENT EVIDENCE") -> INSUFFICIENT EVIDENCE | D44: =IF($B$48,G28,"INSUFFICIENT EVIDENCE") -> INSUFFICIENT EVIDENCE | E44: =IF($B$48,G29,"INSUFFICIENT EVIDENCE") -> INSUFFICIENT EVIDENCE
A45: Warranty claim rate | B45: =IF($B$48,H26,"INSUFFICIENT EVIDENCE") -> INSUFFICIENT EVIDENCE | C45: =IF($B$48,H27,"INSUFFICIENT EVIDENCE") -> INSUFFICIENT EVIDENCE | D45: =IF($B$48,H28,"INSUFFICIENT EVIDENCE") -> INSUFFICIENT EVIDENCE | E45: =IF($B$48,H29,"INSUFFICIENT EVIDENCE") -> INSUFFICIENT EVIDENCE
A46: Data status | B46: =IF(COUNTIF(Object_Log!$A$2:$A$2000,"SAMPLE-*")>0,"DEMO DATA — delete SAMPLE-* rows before use","LIVE DATA") -> DEMO DATA — delete SAMPLE-* rows before use
...

Sheet Customer_Extract
A1: CUSTOMER ENGAGEMENT EXTRACT — CLOSEOUT DELIVERABLE
A2: Per-engagement delivery evidence for the customer: the audit trail behind the rework warranty and the gain-share claim.
A3: Engagement ID | B3: SAMPLE-ENG1
A5: Class | B5: Units delivered | C5: AI-covered share | D5: Avg delivery min/unit | E5: Effort reduction vs agreed baseline | F5: Avg review min | G5: First-pass rate | H5: Rework rate | I5: Warranty incidents
A6: Simple | B6: =COUNTIFS(Object_Log!$C$2:$C$2000,$B$3,Object_Log!$H$2:$H$2000,"Simple",Object_Log!$M$2:$M$2000,"<>Decommission") -> 5 | C6: =IFERROR(COUNTIFS(Object_Log!$C$2:$C$2000,$B$3,Object_Log!$H$2:$H$2000,"Simple",Object_Log!$M$2:$M$2000,"<>Decommission",Object_Log!$P$2:$P$2000,"Y")/B6,0) -> 1 | D6: =IFERROR(AVERAGEIFS(Object_Log!$Q$2:$Q$2000,Object_Log!$C$2:$C$2000,$B$3,Object_Log!$H$2:$H$2000,"Simple",Object_Log!$M$2:$M$2000,"<>Decommission",Object_Log!$P$2:$P$2000,"Y")+AVERAGEIFS(Object_Log!$R$2:$R$2000,Object_Log!$C$2:$C$2000,$B$3,Object_Log!$H$2:$H$2000,"Simple",Object_Log!$M$2:$M$2000,"<>Decommission",Object_Log!$P$2:$P$2000,"Y"),0) -> 24.8 | E6: =IFERROR(1-D6/Dashboard!$B$5,0) -> 0.72444444 | F6: =IFERROR(AVERAGEIFS(Object_Log!$S$2:$S$2000,Object_Log!$C$2:$C$2000,$B$3,Object_Log!$H$2:$H$2000,"Simple",Object_Log!$M$2:$M$2000,"<>Decommission",Object_Log!$P$2:$P$2000,"Y"),0) -> 8.8 | G6: =IFERROR(COUNTIFS(Object_Log!$C$2:$C$2000,$B$3,Object_Log!$H$2:$H$2000,"Simple",Object_Log!$M$2:$M$2000,"<>Decommission",Object_Log!$P$2:$P$2000,"Y",Object_Log!$T$2:$T$2000,"Y")/COUNTIFS(Object_Log!$C$2:$C$2000,$B$3,Object_Log!$H$2:$H$2000,"Simple",Object_Log!$M$2:$M$2000,"<>Decommission",Object_Log!$P$2:$P$2000,"Y"),0) -> 0.8 | H6: =IFERROR(COUNTIFS(Object_Log!$C$2:$C$2000,$B$3,Object_Log!$H$2:$H$2000,"Simple",Object_Log!$M$2:$M$2000,"<>Decommission",Object_Log!$P$2:$P$2000,"Y",Object_Log!$U$2:$U$2000,"Y")/COUNTIFS(Object_Log!$C$2:$C$2000,$B$3,Object_Log!$H$2:$H$2000,"Simple",Object_Log!$M$2:$M$2000,"<>Decommission",Object_Log!$P$2:$P$2000,"Y"),0) -> 0.2 | I6: =COUNTIFS(Object_Log!$C$2:$C$2000,$B$3,Object_Log!$H$2:$H$2000,"Simple",Object_Log!$M$2:$M$2000,"<>Decommission",Object_Log!$Y$2:$Y$2000,"Y") -> 0
A7: Medium | B7: =COUNTIFS(Object_Log!$C$2:$C$2000,$B$3,Object_Log!$H$2:$H$2000,"Medium",Object_Log!$M$2:$M$2000,"<>Decommission") -> 5 | C7: =IFERROR(COUNTIFS(Object_Log!$C$2:$C$2000,$B$3,Object_Log!$H$2:$H$2000,"Medium",Object_Log!$M$2:$M$2000,"<>Decommission",Object_Log!$P$2:$P$2000,"Y")/B7,0) -> 1 | D7: =IFERROR(AVERAGEIFS(Object_Log!$Q$2:$Q$2000,Object_Log!$C$2:$C$2000,$B$3,Object_Log!$H$2:$H$2000,"Medium",Object_Log!$M$2:$M$2000,"<>Decommission",Object_Log!$P$2:$P$2000,"Y")+AVERAGEIFS(Object_Log!$R$2:$R$2000,Object_Log!$C$2:$C$2000,$B$3,Object_Log!$H$2:$H$2000,"Medium",Object_Log!$M$2:$M$2000,"<>Decommission",Object_Log!$P$2:$P$2000,"Y"),0) -> 77.2 | E7: =IFERROR(1-D7/Dashboard!$D$5,0) -> 0.63238095 | F7: =IFERROR(AVERAGEIFS(Object_Log!$S$2:$S$2000,Object_Log!$C$2:$C$2000,$B$3,Object_Log!$H$2:$H$2000,"Medium",Object_Log!$M$2:$M$2000,"<>Decommission",Object_Log!$P$2:$P$2000,"Y"),0) -> 21.2 | G7: =IFERROR(COUNTIFS(Object_Log!$C$2:$C$2000,$B$3,Object_Log!$H$2:$H$2000,"Medium",Object_Log!$M$2:$M$2000,"<>Decommission",Object_Log!$P$2:$P$2000,"Y",Object_Log!$T$2:$T$2000,"Y")/COUNTIFS(Object_Log!$C$2:$C$2000,$B$3,Object_Log!$H$2:$H$2000,"Medium",Object_Log!$M$2:$M$2000,"<>Decommission",Object_Log!$P$2:$P$2000,"Y"),0) -> 0.6 | H7: =IFERROR(COUNTIFS(Object_Log!$C$2:$C$2000,$B$3,Object_Log!$H$2:$H$2000,"Medium",Object_Log!$M$2:$M$2000,"<>Decommission",Object_Log!$P$2:$P$2000,"Y",Object_Log!$U$2:$U$2000,"Y")/COUNTIFS(Object_Log!$C$2:$C$2000,$B$3,Object_Log!$H$2:$H$2000,"Medium",Object_Log!$M$2:$M$2000,"<>Decommission",Object_Log!$P$2:$P$2000,"Y"),0) -> 0.4 | I7: =COUNTIFS(Object_Log!$C$2:$C$2000,$B$3,Object_Log!$H$2:$H$2000,"Medium",Object_Log!$M$2:$M$2000,"<>Decommission",Object_Log!$Y$2:$Y$2000,"Y") -> 1
A8: Complex | B8: =COUNTIFS(Object_Log!$C$2:$C$2000,$B$3,Object_Log!$H$2:$H$2000,"Complex",Object_Log!$M$2:$M$2000,"<>Decommission") -> 5 | C8: =IFERROR(COUNTIFS(Object_Log!$C$2:$C$2000,$B$3,Object_Log!$H$2:$H$2000,"Complex",Object_Log!$M$2:$M$2000,"<>Decommission",Object_Log!$P$2:$P$2000,"Y")/B8,0) -> 0.6 | D8: =IFERROR(AVERAGEIFS(Object_Log!$Q$2:$Q$2000,Object_Log!$C$2:$C$2000,$B$3,Object_Log!$H$2:$H$2000,"Complex",Object_Log!$M$2:$M$2000,"<>Decommission",Object_Log!$P$2:$P$2000,"Y")+AVERAGEIFS(Object_Log!$R$2:$R$2000,Object_Log!$C$2:$C$2000,$B$3,Object_Log!$H$2:$H$2000,"Complex",Object_Log!$M$2:$M$2000,"<>Decommission",Object_Log!$P$2:$P$2000,"Y"),0) -> 210 | E8: =IFERROR(1-D8/Dashboard!$F$5,0) -> 0.5 | F8: =IFERROR(AVERAGEIFS(Object_Log!$S$2:$S$2000,Object_Log!$C$2:$C$2000,$B$3,Object_Log!$H$2:$H$2000,"Complex",Object_Log!$M$2:$M$2000,"<>Decommission",Object_Log!$P$2:$P$2000,"Y"),0) -> 55 | G8: =IFERROR(COUNTIFS(Object_Log!$C$2:$C$2000,$B$3,Object_Log!$H$2:$H$2000,"Complex",Object_Log!$M$2:$M$2000,"<>Decommission",Object_Log!$P$2:$P$2000,"Y",Object_Log!$T$2:$T$2000,"Y")/COUNTIFS(Object_Log!$C$2:$C$2000,$B$3,Object_Log!$H$2:$H$2000,"Complex",Object_Log!$M$2:$M$2000,"<>Decommission",Object_Log!$P$2:$P$2000,"Y"),0) -> 1 | H8: =IFERROR(COUNTIFS(Object_Log!$C$2:$C$2000,$B$3,Object_Log!$H$2:$H$2000,"Complex",Object_Log!$M$2:$M$2000,"<>Decommission",Object_Log!$P$2:$P$2000,"Y",Object_Log!$U$2:$U$2000,"Y")/COUNTIFS(Object_Log!$C$2:$C$2000,$B$3,Object_Log!$H$2:$H$2000,"Complex",Object_Log!$M$2:$M$2000,"<>Decommission",Object_Log!$P$2:$P$2000,"Y"),0) -> 0 | I8: =COUNTIFS(Object_Log!$C$2:$C$2000,$B$3,Object_Log!$H$2:$H$2000,"Complex",Object_Log!$M$2:$M$2000,"<>Decommission",Object_Log!$Y$2:$Y$2000,"Y") -> 0
A9: ALL | B9: =SUM(B6:B8) -> 15 | C9: =IFERROR(SUMPRODUCT(B6:B8,C6:C8)/B9,0) -> 0.86666667 | I9: =SUM(I6:I8) -> 1
A11: Also delivered: units decommissioned instead of remediated (never charged at remediation rates): | F11: =COUNTIFS(Object_Log!$C$2:$C$2000,$B$3,Object_Log!$M$2:$M$2000,"Decommission") -> 1
A13: This extract contains no token, model, cost, rate or margin data. Per-unit telemetry is engagement data under the contract's data-rights clause; the partner retains only anonymized, deidentified aggregates for benchmarking.

Sheet Deal_Log
A1: Quote ID | B1: Date | C1: Customer ID | D1: Offering | E1: Competitor type | F1: Competitor price/unit ($) | G1: Our price/unit ($) | H1: Outcome | I1: Loss reason | J1: Notes
A2: SAMPLE-Q1 | B2: 2026-07-01 | C2: SAMPLE-CUST1 | D2: Custom code remediation | E2: Offshore T&M | F2: 195 | G2: 249 | H2: Won | J2: won on speed + warranty despite higher unit price
A3: SAMPLE-Q2 | B3: 2026-07-10 | C3: SAMPLE-CUST2 | D3: Test script automation | E3: AI-native | F3: 140 | G3: 240 | H3: Lost | I3: Price — AI-native bid far below floor | J3: validated alternative was the competing bid, not our rate card
A5: MARKET CALIBRATION (computes live)
A6: Win rate (decided quotes) | B6: =IFERROR(COUNTIF($H$2:$H$2000,"Won")/(COUNTIF($H$2:$H$2000,"Won")+COUNTIF($H$2:$H$2000,"Lost")),0) -> 0.5
A7: Avg competing price/unit — AI-native | B7: =IFERROR(AVERAGEIFS($F$2:$F$2000,$E$2:$E$2000,"AI-native"),"—") -> 140
A8: Avg competing price/unit — Offshore T&M | B8: =IFERROR(AVERAGEIFS($F$2:$F$2000,$E$2:$E$2000,"Offshore T&M"),"—") -> 195
A9: Avg competing price/unit — Incumbent renewal | B9: =IFERROR(AVERAGEIFS($F$2:$F$2000,$E$2:$E$2000,"Incumbent renewal"),"—") -> —
A10: Avg competing price/unit — Internal team | B10: =IFERROR(AVERAGEIFS($F$2:$F$2000,$E$2:$E$2000,"Internal team"),"—") -> —
A12: Use these observed prices — not the internal rate card — as the validated customer alternative in the calculator's anchor block.

Sheet Service_Log
A1: Period (YYYY-MM) | B1: Contract ID | C1: Customer ID | D1: Service type | E1: AI Minutes | F1: Human Minutes | G1: Review Minutes | H1: Rework (Y/N) | I1: Tokens In (K) | J1: Tokens Out (K) | K1: Model + Version | L1: Notes
A2: 2026-07 | B2: SAMPLE-CT1 | C2: SAMPLE-CUST1 | D2: AMS ticket resolved | E2: 6 | F2: 18 | G2: 8 | H2: N | I2: 120 | J2: 15 | K2: Sonnet 4.6 (2026-05) | L2: P3 incident
A3: 2026-07 | B3: SAMPLE-CT1 | C3: SAMPLE-CUST1 | D3: Monitoring alert triaged | E3: 2 | F3: 5 | G3: 0 | H3: N | I3: 40 | J3: 4 | K3: Sonnet 4.6 (2026-05)

Sheet Contract_Log
A1: Contract ID | B1: Customer ID | C1: Start date | D1: Term (months) | E1: Annual fee ($) | F1: Included units/yr | G1: Renewal outcome | H1: Units consumed (logged) | I1: Support minutes (logged) | J1: Minutes per unit
A2: SAMPLE-CT1 | B2: SAMPLE-CUST1 | C2: 2026-07-01 | D2: 12 | E2: 180000 | F2: 600 | G2: Pending | H2: =COUNTIFS(Service_Log!$B$2:$B$2000,$A2) -> 2 | I2: =SUMIFS(Service_Log!$E$2:$E$2000,Service_Log!$B$2:$B$2000,$A2)+SUMIFS(Service_Log!$F$2:$F$2000,Service_Log!$B$2:$B$2000,$A2)+SUMIFS(Service_Log!$G$2:$G$2000,Service_Log!$B$2:$B$2000,$A2) -> 39 | J2: =IFERROR(I2/H2,0) -> 19.5
A5: SUBSCRIPTION EVIDENCE (computes live)
A6: Gross renewal rate (decided contracts) | B6: =IFERROR(COUNTIF($G$2:$G$2000,"Y")/(COUNTIF($G$2:$G$2000,"Y")+COUNTIF($G$2:$G$2000,"N")),0) -> 0
A8: Subscription offers are quoted only from measured cost-to-serve and observed renewals — treat as defensible from ~12 contract-months across ≥5 contracts. Until then the calculator's subscription fields are unevidenced heuristics.
